[2022-07-16 21:57:31,344] {taskinstance.py:1160} INFO - Dependencies all met for <TaskInstance: local_to_gcs.local_to_gcs_task manual__2022-07-16T21:57:30.322447+00:00 [queued]>
[2022-07-16 21:57:31,353] {taskinstance.py:1160} INFO - Dependencies all met for <TaskInstance: local_to_gcs.local_to_gcs_task manual__2022-07-16T21:57:30.322447+00:00 [queued]>
[2022-07-16 21:57:31,354] {taskinstance.py:1357} INFO - 
--------------------------------------------------------------------------------
[2022-07-16 21:57:31,356] {taskinstance.py:1358} INFO - Starting attempt 1 of 1
[2022-07-16 21:57:31,357] {taskinstance.py:1359} INFO - 
--------------------------------------------------------------------------------
[2022-07-16 21:57:31,368] {taskinstance.py:1378} INFO - Executing <Task(LocalFilesystemToGCSOperator): local_to_gcs_task> on 2022-07-16 21:57:30.322447+00:00
[2022-07-16 21:57:31,374] {standard_task_runner.py:52} INFO - Started process 3104 to run task
[2022-07-16 21:57:31,377] {standard_task_runner.py:79} INFO - Running: ['***', 'tasks', 'run', 'local_to_gcs', 'local_to_gcs_task', 'manual__2022-07-16T21:57:30.322447+00:00', '--job-id', '12', '--raw', '--subdir', 'DAGS_FOLDER/local_to_gcs.py', '--cfg-path', '/tmp/tmp5rbbiu3k', '--error-file', '/tmp/tmpgv9cbhyo']
[2022-07-16 21:57:31,380] {standard_task_runner.py:80} INFO - Job 12: Subtask local_to_gcs_task
[2022-07-16 21:57:31,428] {task_command.py:370} INFO - Running <TaskInstance: local_to_gcs.local_to_gcs_task manual__2022-07-16T21:57:30.322447+00:00 [running]> on host 32d1f26135d5
[2022-07-16 21:57:31,493] {taskinstance.py:1572} INFO - Exporting the following env vars:
AIRFLOW_CTX_DAG_OWNER=***
AIRFLOW_CTX_DAG_ID=local_to_gcs
AIRFLOW_CTX_TASK_ID=local_to_gcs_task
AIRFLOW_CTX_EXECUTION_DATE=2022-07-16T21:57:30.322447+00:00
AIRFLOW_CTX_TRY_NUMBER=1
AIRFLOW_CTX_DAG_RUN_ID=manual__2022-07-16T21:57:30.322447+00:00
[2022-07-16 21:57:31,497] {crypto.py:82} WARNING - empty cryptography key - values will not be stored encrypted.
[2022-07-16 21:57:31,498] {base.py:68} INFO - Using connection ID 'google_cloud_default' for task execution.
[2022-07-16 21:57:31,504] {taskinstance.py:1890} ERROR - Task failed with exception
Traceback (most recent call last):
  File "/home/airflow/.local/lib/python3.7/site-packages/airflow/providers/google/cloud/transfers/local_to_gcs.py", line 100, in execute
    raise FileNotFoundError(self.src)
FileNotFoundError: /Users/giovanibaroni/data-engineering/final_project/country_partner_1999.csv
[2022-07-16 21:57:31,513] {taskinstance.py:1401} INFO - Marking task as FAILED. dag_id=local_to_gcs, task_id=local_to_gcs_task, execution_date=20220716T215730, start_date=20220716T215731, end_date=20220716T215731
[2022-07-16 21:57:31,524] {standard_task_runner.py:97} ERROR - Failed to execute job 12 for task local_to_gcs_task (/Users/giovanibaroni/data-engineering/final_project/country_partner_1999.csv; 3104)
[2022-07-16 21:57:31,553] {local_task_job.py:156} INFO - Task exited with return code 1
[2022-07-16 21:57:31,606] {local_task_job.py:273} INFO - 0 downstream tasks scheduled from follow-on schedule check
