[2022-07-18 22:11:08,961] {taskinstance.py:1160} INFO - Dependencies all met for <TaskInstance: local_to_gcs.local_to_gcs_task manual__2022-07-18T22:11:05.784067+00:00 [queued]>
[2022-07-18 22:11:08,973] {taskinstance.py:1160} INFO - Dependencies all met for <TaskInstance: local_to_gcs.local_to_gcs_task manual__2022-07-18T22:11:05.784067+00:00 [queued]>
[2022-07-18 22:11:08,974] {taskinstance.py:1357} INFO - 
--------------------------------------------------------------------------------
[2022-07-18 22:11:08,976] {taskinstance.py:1358} INFO - Starting attempt 1 of 1
[2022-07-18 22:11:08,977] {taskinstance.py:1359} INFO - 
--------------------------------------------------------------------------------
[2022-07-18 22:11:08,993] {taskinstance.py:1378} INFO - Executing <Task(PythonOperator): local_to_gcs_task> on 2022-07-18 22:11:05.784067+00:00
[2022-07-18 22:11:09,004] {standard_task_runner.py:52} INFO - Started process 35375 to run task
[2022-07-18 22:11:09,008] {standard_task_runner.py:79} INFO - Running: ['***', 'tasks', 'run', 'local_to_gcs', 'local_to_gcs_task', 'manual__2022-07-18T22:11:05.784067+00:00', '--job-id', '26', '--raw', '--subdir', 'DAGS_FOLDER/local_to_gcs.py', '--cfg-path', '/tmp/tmpieu7poa7', '--error-file', '/tmp/tmprltwim7r']
[2022-07-18 22:11:09,010] {standard_task_runner.py:80} INFO - Job 26: Subtask local_to_gcs_task
[2022-07-18 22:11:09,071] {task_command.py:370} INFO - Running <TaskInstance: local_to_gcs.local_to_gcs_task manual__2022-07-18T22:11:05.784067+00:00 [running]> on host 32d1f26135d5
[2022-07-18 22:11:09,180] {taskinstance.py:1572} INFO - Exporting the following env vars:
AIRFLOW_CTX_DAG_OWNER=***
AIRFLOW_CTX_DAG_ID=local_to_gcs
AIRFLOW_CTX_TASK_ID=local_to_gcs_task
AIRFLOW_CTX_EXECUTION_DATE=2022-07-18T22:11:05.784067+00:00
AIRFLOW_CTX_TRY_NUMBER=1
AIRFLOW_CTX_DAG_RUN_ID=manual__2022-07-18T22:11:05.784067+00:00
[2022-07-18 22:11:09,245] {taskinstance.py:1890} ERROR - Task failed with exception
Traceback (most recent call last):
  File "/home/airflow/.local/lib/python3.7/site-packages/airflow/operators/python.py", line 171, in execute
    return_value = self.execute_callable()
  File "/home/airflow/.local/lib/python3.7/site-packages/airflow/operators/python.py", line 189, in execute_callable
    return self.python_callable(*self.op_args, **self.op_kwargs)
  File "/opt/airflow/dags/local_to_gcs.py", line 57, in upload_to_gcs
    blob.upload_from_filename(local_file)
  File "/home/airflow/.local/lib/python3.7/site-packages/google/cloud/storage/blob.py", line 2720, in upload_from_filename
    with open(filename, "rb") as file_obj:
FileNotFoundError: [Errno 2] No such file or directory: '/country_partner_1999.csv'
[2022-07-18 22:11:09,262] {taskinstance.py:1401} INFO - Marking task as FAILED. dag_id=local_to_gcs, task_id=local_to_gcs_task, execution_date=20220718T221105, start_date=20220718T221108, end_date=20220718T221109
[2022-07-18 22:11:09,274] {standard_task_runner.py:97} ERROR - Failed to execute job 26 for task local_to_gcs_task ([Errno 2] No such file or directory: '/country_partner_1999.csv'; 35375)
[2022-07-18 22:11:09,308] {local_task_job.py:156} INFO - Task exited with return code 1
[2022-07-18 22:11:09,345] {local_task_job.py:273} INFO - 0 downstream tasks scheduled from follow-on schedule check
