[2022-07-16 23:03:41,384] {taskinstance.py:1160} INFO - Dependencies all met for <TaskInstance: local_to_gcs.local_to_gcs_task manual__2022-07-16T23:03:39.656752+00:00 [queued]>
[2022-07-16 23:03:41,395] {taskinstance.py:1160} INFO - Dependencies all met for <TaskInstance: local_to_gcs.local_to_gcs_task manual__2022-07-16T23:03:39.656752+00:00 [queued]>
[2022-07-16 23:03:41,397] {taskinstance.py:1357} INFO - 
--------------------------------------------------------------------------------
[2022-07-16 23:03:41,399] {taskinstance.py:1358} INFO - Starting attempt 1 of 1
[2022-07-16 23:03:41,401] {taskinstance.py:1359} INFO - 
--------------------------------------------------------------------------------
[2022-07-16 23:03:41,415] {taskinstance.py:1378} INFO - Executing <Task(LocalFilesystemToGCSOperator): local_to_gcs_task> on 2022-07-16 23:03:39.656752+00:00
[2022-07-16 23:03:41,428] {standard_task_runner.py:52} INFO - Started process 4088 to run task
[2022-07-16 23:03:41,433] {standard_task_runner.py:79} INFO - Running: ['***', 'tasks', 'run', 'local_to_gcs', 'local_to_gcs_task', 'manual__2022-07-16T23:03:39.656752+00:00', '--job-id', '15', '--raw', '--subdir', 'DAGS_FOLDER/local_to_gcs.py', '--cfg-path', '/tmp/tmp9cn41vpn', '--error-file', '/tmp/tmpty52ll0w']
[2022-07-16 23:03:41,435] {standard_task_runner.py:80} INFO - Job 15: Subtask local_to_gcs_task
[2022-07-16 23:03:41,502] {task_command.py:370} INFO - Running <TaskInstance: local_to_gcs.local_to_gcs_task manual__2022-07-16T23:03:39.656752+00:00 [running]> on host 32d1f26135d5
[2022-07-16 23:03:41,583] {taskinstance.py:1572} INFO - Exporting the following env vars:
AIRFLOW_CTX_DAG_OWNER=***
AIRFLOW_CTX_DAG_ID=local_to_gcs
AIRFLOW_CTX_TASK_ID=local_to_gcs_task
AIRFLOW_CTX_EXECUTION_DATE=2022-07-16T23:03:39.656752+00:00
AIRFLOW_CTX_TRY_NUMBER=1
AIRFLOW_CTX_DAG_RUN_ID=manual__2022-07-16T23:03:39.656752+00:00
[2022-07-16 23:03:41,588] {crypto.py:82} WARNING - empty cryptography key - values will not be stored encrypted.
[2022-07-16 23:03:41,589] {base.py:68} INFO - Using connection ID 'google_cloud_default' for task execution.
[2022-07-16 23:03:41,591] {taskinstance.py:1890} ERROR - Task failed with exception
Traceback (most recent call last):
  File "/home/airflow/.local/lib/python3.7/site-packages/airflow/providers/google/cloud/transfers/local_to_gcs.py", line 100, in execute
    raise FileNotFoundError(self.src)
FileNotFoundError: /Users/giovanibaroni/data-engineering/final_project/country_partner_1999.csv
[2022-07-16 23:03:41,605] {taskinstance.py:1401} INFO - Marking task as FAILED. dag_id=local_to_gcs, task_id=local_to_gcs_task, execution_date=20220716T230339, start_date=20220716T230341, end_date=20220716T230341
[2022-07-16 23:03:41,616] {standard_task_runner.py:97} ERROR - Failed to execute job 15 for task local_to_gcs_task (/Users/giovanibaroni/data-engineering/final_project/country_partner_1999.csv; 4088)
[2022-07-16 23:03:41,649] {local_task_job.py:156} INFO - Task exited with return code 1
[2022-07-16 23:03:41,698] {local_task_job.py:273} INFO - 0 downstream tasks scheduled from follow-on schedule check
