[2022-07-16 23:06:38,701] {taskinstance.py:1160} INFO - Dependencies all met for <TaskInstance: local_to_gcs.local_to_gcs_task manual__2022-07-16T23:06:37.850516+00:00 [queued]>
[2022-07-16 23:06:38,710] {taskinstance.py:1160} INFO - Dependencies all met for <TaskInstance: local_to_gcs.local_to_gcs_task manual__2022-07-16T23:06:37.850516+00:00 [queued]>
[2022-07-16 23:06:38,711] {taskinstance.py:1357} INFO - 
--------------------------------------------------------------------------------
[2022-07-16 23:06:38,712] {taskinstance.py:1358} INFO - Starting attempt 1 of 1
[2022-07-16 23:06:38,713] {taskinstance.py:1359} INFO - 
--------------------------------------------------------------------------------
[2022-07-16 23:06:38,725] {taskinstance.py:1378} INFO - Executing <Task(LocalFilesystemToGCSOperator): local_to_gcs_task> on 2022-07-16 23:06:37.850516+00:00
[2022-07-16 23:06:38,732] {standard_task_runner.py:52} INFO - Started process 4246 to run task
[2022-07-16 23:06:38,736] {standard_task_runner.py:79} INFO - Running: ['***', 'tasks', 'run', 'local_to_gcs', 'local_to_gcs_task', 'manual__2022-07-16T23:06:37.850516+00:00', '--job-id', '17', '--raw', '--subdir', 'DAGS_FOLDER/local_to_gcs.py', '--cfg-path', '/tmp/tmp6xqv9v1x', '--error-file', '/tmp/tmpq2qw0b__']
[2022-07-16 23:06:38,739] {standard_task_runner.py:80} INFO - Job 17: Subtask local_to_gcs_task
[2022-07-16 23:06:38,807] {task_command.py:370} INFO - Running <TaskInstance: local_to_gcs.local_to_gcs_task manual__2022-07-16T23:06:37.850516+00:00 [running]> on host 32d1f26135d5
[2022-07-16 23:06:38,903] {taskinstance.py:1572} INFO - Exporting the following env vars:
AIRFLOW_CTX_DAG_OWNER=***
AIRFLOW_CTX_DAG_ID=local_to_gcs
AIRFLOW_CTX_TASK_ID=local_to_gcs_task
AIRFLOW_CTX_EXECUTION_DATE=2022-07-16T23:06:37.850516+00:00
AIRFLOW_CTX_TRY_NUMBER=1
AIRFLOW_CTX_DAG_RUN_ID=manual__2022-07-16T23:06:37.850516+00:00
[2022-07-16 23:06:38,907] {crypto.py:82} WARNING - empty cryptography key - values will not be stored encrypted.
[2022-07-16 23:06:38,909] {base.py:68} INFO - Using connection ID 'google_cloud_default' for task execution.
[2022-07-16 23:06:38,913] {taskinstance.py:1890} ERROR - Task failed with exception
Traceback (most recent call last):
  File "/home/airflow/.local/lib/python3.7/site-packages/airflow/providers/google/cloud/transfers/local_to_gcs.py", line 100, in execute
    raise FileNotFoundError(self.src)
FileNotFoundError: country_partner_1999.csv
[2022-07-16 23:06:38,924] {taskinstance.py:1401} INFO - Marking task as FAILED. dag_id=local_to_gcs, task_id=local_to_gcs_task, execution_date=20220716T230637, start_date=20220716T230638, end_date=20220716T230638
[2022-07-16 23:06:38,937] {standard_task_runner.py:97} ERROR - Failed to execute job 17 for task local_to_gcs_task (country_partner_1999.csv; 4246)
[2022-07-16 23:06:38,953] {local_task_job.py:156} INFO - Task exited with return code 1
[2022-07-16 23:06:38,994] {local_task_job.py:273} INFO - 0 downstream tasks scheduled from follow-on schedule check
