[2022-07-16 21:07:17,524] {taskinstance.py:1160} INFO - Dependencies all met for <TaskInstance: local_to_gcs.local_to_gcs_task manual__2022-07-16T21:07:16.516594+00:00 [queued]>
[2022-07-16 21:07:17,533] {taskinstance.py:1160} INFO - Dependencies all met for <TaskInstance: local_to_gcs.local_to_gcs_task manual__2022-07-16T21:07:16.516594+00:00 [queued]>
[2022-07-16 21:07:17,535] {taskinstance.py:1357} INFO - 
--------------------------------------------------------------------------------
[2022-07-16 21:07:17,537] {taskinstance.py:1358} INFO - Starting attempt 1 of 1
[2022-07-16 21:07:17,539] {taskinstance.py:1359} INFO - 
--------------------------------------------------------------------------------
[2022-07-16 21:07:17,556] {taskinstance.py:1378} INFO - Executing <Task(PythonOperator): local_to_gcs_task> on 2022-07-16 21:07:16.516594+00:00
[2022-07-16 21:07:17,565] {standard_task_runner.py:52} INFO - Started process 390 to run task
[2022-07-16 21:07:17,570] {standard_task_runner.py:79} INFO - Running: ['***', 'tasks', 'run', 'local_to_gcs', 'local_to_gcs_task', 'manual__2022-07-16T21:07:16.516594+00:00', '--job-id', '5', '--raw', '--subdir', 'DAGS_FOLDER/local_to_gcs.py', '--cfg-path', '/tmp/tmpk00f851l', '--error-file', '/tmp/tmptiitdpts']
[2022-07-16 21:07:17,573] {standard_task_runner.py:80} INFO - Job 5: Subtask local_to_gcs_task
[2022-07-16 21:07:17,632] {task_command.py:370} INFO - Running <TaskInstance: local_to_gcs.local_to_gcs_task manual__2022-07-16T21:07:16.516594+00:00 [running]> on host 32d1f26135d5
[2022-07-16 21:07:17,701] {taskinstance.py:1572} INFO - Exporting the following env vars:
AIRFLOW_CTX_DAG_OWNER=***
AIRFLOW_CTX_DAG_ID=local_to_gcs
AIRFLOW_CTX_TASK_ID=local_to_gcs_task
AIRFLOW_CTX_EXECUTION_DATE=2022-07-16T21:07:16.516594+00:00
AIRFLOW_CTX_TRY_NUMBER=1
AIRFLOW_CTX_DAG_RUN_ID=manual__2022-07-16T21:07:16.516594+00:00
[2022-07-16 21:07:17,740] {taskinstance.py:1890} ERROR - Task failed with exception
Traceback (most recent call last):
  File "/home/airflow/.local/lib/python3.7/site-packages/airflow/operators/python.py", line 171, in execute
    return_value = self.execute_callable()
  File "/home/airflow/.local/lib/python3.7/site-packages/airflow/operators/python.py", line 189, in execute_callable
    return self.python_callable(*self.op_args, **self.op_kwargs)
  File "/opt/airflow/dags/local_to_gcs.py", line 50, in upload_to_gcs
    blob.upload_from_filename(local_file)
  File "/home/airflow/.local/lib/python3.7/site-packages/google/cloud/storage/blob.py", line 2720, in upload_from_filename
    with open(filename, "rb") as file_obj:
FileNotFoundError: [Errno 2] No such file or directory: '/opt/airflow/country_partner_1999.csv'
[2022-07-16 21:07:17,756] {taskinstance.py:1401} INFO - Marking task as FAILED. dag_id=local_to_gcs, task_id=local_to_gcs_task, execution_date=20220716T210716, start_date=20220716T210717, end_date=20220716T210717
[2022-07-16 21:07:17,772] {standard_task_runner.py:97} ERROR - Failed to execute job 5 for task local_to_gcs_task ([Errno 2] No such file or directory: '/opt/airflow/country_partner_1999.csv'; 390)
[2022-07-16 21:07:17,787] {local_task_job.py:156} INFO - Task exited with return code 1
[2022-07-16 21:07:17,828] {local_task_job.py:273} INFO - 0 downstream tasks scheduled from follow-on schedule check
